Workbook

Sheet Read me
A1: Same Budget, More Water - WaPOR Hackathon 2026, Team 39
A2: Targeting Egypt's on-farm modernisation budget using the WaPOR v3 evaporation/transpiration split
A4: Source: FAO WaPOR v3 Level 2 (100 m, dekadal)
A7: THE IDEA
A8: IPAT - the irrigation assessment tool already operating at Egypt's Ministry of Water Resources and Irrigation,
A9: on WaPOR v3 Level 3 (20 m) across ~1.5 Mha of the Middle and West Delta - shows WHERE productivity is high
A10: and low. It stops there. A ministry with a fixed budget still has to decide WHERE TO SPEND.
A12: WaPOR reports evaporation (E) and transpiration (T) separately. T grew a crop; E did not. Ranking districts
A13: by how much evaporated water is recoverable, and what it costs to recover it, turns a map into a spending list.
A15: SHEETS
A16: Assumptions intervention cost model. EDIT THE YELLOW CELLS - everything else recalculates.
A17: Districts per-governorate WaPOR statistics and derived water balance
... A35: not water accounting.

Sheet Assumptions
A1: Intervention cost model
A2: Literature-order ESTIMATES, not measurements. Yellow cells are inputs - change them and every other sheet recalculates.
A4: Intervention | B4: Cost USD/ha | C4: Life, years | D4: Evap. avoided | E4: Seasons/yr | F4: Applies to | G4: Note
A5: Laser land levelling | B5: 75 | C5: 5 | D5: 0.1 | E5: 2 | F5: Delta - rice belt, Delta - other, Nile Valley | G5: Reduces ponding depth and over-irrigation of high spots, so less standing water and less saturated soil surface. Already deployed at scale in Egypt, so cost and effect are the best constrained of the four. Benefits both summer and winter crops.
A6: Alternate wetting & drying (rice) | B6: 25 | C6: 1 | D6: 0.1 | E6: 1 | F6: Delta - rice belt | G6: Training + field water tubes. IMPORTANT: AWD's headline saving in the literature is in water APPLIED - percolation and seepage - not in evapotranspiration. In the closed, high-reuse Delta, percolation is largely recovered downstream, so we deliberately exclude it and count ONLY the evaporation component: removing the free water surface for part of the season. Hence 10%, not the 25-30% quoted for total water application.
A7: Straw / plastic mulching | B7: 260 | C7: 1 | D7: 0.3 | E7: 1 | F7: Delta - other, Nile Valley | G7: Suppresses bare-soil evaporation between rows. Caveat: some of the conserved soil water is taken up and transpired instead, converting E to T and yield rather than to saved water - good agronomy, zero water volume. Treat as an upper bound.
A8: Drip retrofit | B8: 1800 | C8: 10 | D8: 0.45 | E8: 2 | F8: Delta - other, Nile Valley | G8: Largest saving, largest capital cost, and the same E-to-T compensation caveat as mulching. Not viable for paddy rice.
A10: Budget, USD | B10: 12000000
A11: Season | B11: Summer (Nili/Sefi) 2024
A13: Source: literature-order estimates compiled by Team 39, corrected after adversarial review. See docs/ASSUMPTIONS.md.

Sheet Districts
A1: Governorate | B1: System | C1: Irrigated ha | D1: AETI mm | E1: E mm | F1: T mm | G1: I mm | H1: Beneficial fraction | I1: Non-beneficial Mm3 | J1: Confidence
A2: Aswan | B2: Nile Valley | C2: 79350 | D2: 737.6 | E2: 186 | F2: 551.6 | G2: 0 | H2: =IF(D2=0,0,F2/D2) | I2: =E2*C2*10/1000000 | J2: medium
A3: Qena | B3: Nile Valley | C3: 182502 | D3: 774.4 | E3: 185.8 | F3: 588.6 | G3: 0 | H3: =IF(D3=0,0,F3/D3) | I3: =E3*C3*10/1000000 | J3: medium
A4: Sohag | B4: Nile Valley | C4: 144522 | D4: 703.9 | E4: 175.9 | F4: 527.7 | G4: 0.2 | H4: =IF(D4=0,0,F4/D4) | I4: =E4*C4*10/1000000 | J4: high
A5: Assiut | B5: Nile Valley | C5: 148668 | D5: 688 | E5: 162.6 | F5: 525.3 | G5: 0.2 | H5: =IF(D5=0,0,F5/D5) | I5: =E5*C5*10/1000000 | J5: high
A6: Beni Suef | B6: Nile Valley | C6: 131054 | D6: 680.4 | E6: 159.2 | F6: 521.1 | G6: 0 | H6: =IF(D6=0,0,F6/D6) | I6: =E6*C6*10/1000000 | J6: high
A7: Qalyubia | B7: Delta - other | C7: 74955 | D7: 589.9 | E7: 152.9 | F7: 436.9 | G7: 0 | H7: =IF(D7=0,0,F7/D7) | I7: =E7*C7*10/1000000 | J7: high
A8: Minya | B8: Nile Valley | C8: 240743 | D8: 660.4 | E8: 151.9 | F8: 508.5 | G8: 0 | H8: =IF(D8=0,0,F8/D8) | I8: =E8*C8*10/1000000 | J8: high
A9: Fayoum | B9: Nile Valley | C9: 154609 | D9: 608.1 | E9: 148.7 | F9: 459.4 | G9: 0 | H9: =IF(D9=0,0,F9/D9) | I9: =E9*C9*10/1000000 | J9: high
A10: Menoufia | B10: Delta - other | C10: 135139 | D10: 610.6 | E10: 148.4 | F10: 462.2 | G10: 0 | H10: =IF(D10=0,0,F10/D10) | I10: =E10*C10*10/1000000 | J10: high
A11: Sharqia | B11: Delta - rice belt | C11: 393385 | D11: 594.9 | E11: 143.8 | F11: 451.1 | G11: 0 | H11: =IF(D11=0,0,F11/D11) | I11: =E11*C11*10/1000000 | J11: high
A12: Gharbia | B12: Delta - other | C12: 177584 | D12: 629.8 | E12: 143.6 | F12: 486.2 | G12: 0 | H12: =IF(D12=0,0,F12/D12) | I12: =E12*C12*10/1000000 | J12: high
A13: Giza | B13: Nile Valley | C13: 107064 | D13: 524.3 | E13: 138.3 | F13: 386 | G13: 0 | H13: =IF(D13=0,0,F13/D13) | I13: =E13*C13*10/1000000 | J13: medium
... A19: Alexandria | B19: Delta - other | C19: 70687 | D19: 364.4 | E19: 79.4 | F19: 284.9 | G19: 0.1 | H19: =IF(D19=0,0,F19/D19) | I19: =E19*C19*10/1000000 | J19: high
A20: TOTAL | C20: =SUM(C2:C19) | I20: =SUM(I2:I19)
A22: Blue = WaPOR v3 L2 (100 m) seasonal values.
A23: Non-beneficial Mm3 = E_mm x irrigated_ha x 10 / 1e6. Beneficial fraction = T / AETI.
A24: Confidence caveat: the CV is computed over the already-masked subset, so a mostly-desert governorate can score high. Fix before Phase 2.

Sheet Ranked options
A1: Rank | B1: Governorate | C1: System | D1: Intervention | E1: Irrigated ha | F1: E mm | G1: Recoverable Mm3 | H1: Annual cost USD | I1: USD per m3 | J1: Confidence
A2: 1 | B2: Aswan | C2: Nile Valley | D2: Laser land levelling | E2: =Districts!C2 | F2: =Districts!E2 | G2: =F2*E2*10*Assumptions!$D$5*Assumptions!$E$5/1000000 | H2: =Assumptions!$B$5/Assumptions!$C$5*E2 | I2: =IF(G2=0,0,H2/(G2*1000000)) | J2: medium
A3: 2 | B3: Qena | C3: Nile Valley | D3: Laser land levelling | E3: =Districts!C3 | F3: =Districts!E3 | G3: =F3*E3*10*Assumptions!$D$5*Assumptions!$E$5/1000000 | H3: =Assumptions!$B$5/Assumptions!$C$5*E3 | I3: =IF(G3=0,0,H3/(G3*1000000)) | J3: medium
A4: 3 | B4: Sohag | C4: Nile Valley | D4: Laser land levelling | E4: =Districts!C4 | F4: =Districts!E4 | G4: =F4*E4*10*Assumptions!$D$5*Assumptions!$E$5/1000000 | H4: =Assumptions!$B$5/Assumptions!$C$5*E4 | I4: =IF(G4=0,0,H4/(G4*1000000)) | J4: high
A5: 4 | B5: Assiut | C5: Nile Valley | D5: Laser land levelling | E5: =Districts!C5 | F5: =Districts!E5 | G5: =F5*E5*10*Assumptions!$D$5*Assumptions!$E$5/1000000 | H5: =Assumptions!$B$5/Assumptions!$C$5*E5 | I5: =IF(G5=0,0,H5/(G5*1000000)) | J5: high
A6: 5 | B6: Beni Suef | C6: Nile Valley | D6: Laser land levelling | E6: =Districts!C6 | F6: =Districts!E6 | G6: =F6*E6*10*Assumptions!$D$5*Assumptions!$E$5/1000000 | H6: =Assumptions!$B$5/Assumptions!$C$5*E6 | I6: =IF(G6=0,0,H6/(G6*1000000)) | J6: high
A7: 6 | B7: Qalyubia | C7: Delta - other | D7: Laser land levelling | E7: =Districts!C7 | F7: =Districts!E7 | G7: =F7*E7*10*Assumptions!$D$5*Assumptions!$E$5/1000000 | H7: =Assumptions!$B$5/Assumptions!$C$5*E7 | I7: =IF(G7=0,0,H7/(G7*1000000)) | J7: high
A8: 7 | B8: Minya | C8: Nile Valley | D8: Laser land levelling | E8: =Districts!C8 | F8: =Districts!E8 | G8: =F8*E8*10*Assumptions!$D$5*Assumptions!$E$5/1000000 | H8: =Assumptions!$B$5/Assumptions!$C$5*E8 | I8: =IF(G8=0,0,H8/(G8*1000000)) | J8: high
A9: 8 | B9: Fayoum | C9: Nile Valley | D9: Laser land levelling | E9: =Districts!C9 | F9: =Districts!E9 | G9: =F9*E9*10*Assumptions!$D$5*Assumptions!$E$5/1000000 | H9: =Assumptions!$B$5/Assumptions!$C$5*E9 | I9: =IF(G9=0,0,H9/(G9*1000000)) | J9: high
A10: 9 | B10: Menoufia | C10: Delta - other | D10: Laser land levelling | E10: =Districts!C10 | F10: =Districts!E10 | G10: =F10*E10*10*Assumptions!$D$5*Assumptions!$E$5/1000000 | H10: =Assumptions!$B$5/Assumptions!$C$5*E10 | I10: =IF(G10=0,0,H10/(G10*1000000)) | J10: high
A11: 10 | B11: Sharqia | C11: Delta - rice belt | D11: Laser land levelling | E11: =Districts!C11 | F11: =Districts!E11 | G11: =F11*E11*10*Assumptions!$D$5*Assumptions!$E$5/1000000 | H11: =Assumptions!$B$5/Assumptions!$C$5*E11 | I11: =IF(G11=0,0,H11/(G11*1000000)) | J11: high
A12: 11 | B12: Gharbia | C12: Delta - other | D12: Laser land levelling | E12: =Districts!C12 | F12: =Districts!E12 | G12: =F12*E12*10*Assumptions!$D$5*Assumptions!$E$5/1000000 | H12: =Assumptions!$B$5/Assumptions!$C$5*E12 | I12: =IF(G12=0,0,H12/(G12*1000000)) | J12: high
A13: 12 | B13: Giza | C13: Nile Valley | D13: Laser land levelling | E13: =Districts!C13 | F13: =Districts!E13 | G13: =F13*E13*10*Assumptions!$D$5*Assumptions!$E$5/1000000 | H13: =Assumptions!$B$5/Assumptions!$C$5*E13 | I13: =IF(G13=0,0,H13/(G13*1000000)) | J13: medium
... A19: 18 | B19: Alexandria | C19: Delta - other | D19: Laser land levelling | E19: =Districts!C19 | F19: =Districts!E19 | G19: =F19*E19*10*Assumptions!$D$5*Assumptions!$E$5/1000000 | H19: =Assumptions!$B$5/Assumptions!$C$5*E19 | I19: =IF(G19=0,0,H19/(G19*1000000)) | J19: high
A20: 19 | B20: Aswan | C20: Nile Valley | D20: Drip retrofit | E20: =Districts!C2 | F20: =Districts!E2 | G20: =F20*E20*10*Assumptions!$D$8*Assumptions!$E$8/1000000 | H20: =Assumptions!$B$8/Assumptions!$C$8*E20 | I20: =IF(G20=0,0,H20/(G20*1000000)) | J20: medium
A21: 20 | B21: Qena | C21: Nile Valley | D21: Drip retrofit | E21: =Districts!C3 | F21: =Districts!E3 | G21: =F21*E21*10*Assumptions!$D$8*Assumptions!$E$8/1000000 | H21: =Assumptions!$B$8/Assumptions!$C$8*E21 | I21: =IF(G21=0,0,H21/(G21*1000000)) | J21: medium
A22: 21 | B22: Sohag | C22: Nile Valley | D22: Drip retrofit | E22: =Districts!C4 | F22: =Districts!E4 | G22: =F22*E22*10*Assumptions!$D$8*Assumptions!$E$8/1000000 | H22: =Assumptions!$B$8/Assumptions!$C$8*E22 | I22: =IF(G22=0,0,H22/(G22*1000000)) | J22: high
A23: 22 | B23: Assiut | C23: Nile Valley | D23: Drip retrofit | E23: =Districts!C5 | F23: =Districts!E5 | G23: =F23*E23*10*Assumptions!$D$8*Assumptions!$E$8/1000000 | H23: =Assumptions!$B$8/Assumptions!$C$8*E23 | I23: =IF(G23=0,0,H23/(G23*1000000)) | J23: high
A24: 23 | B24: Beni Suef | C24: Nile Valley | D24: Drip retrofit | E24: =Districts!C6 | F24: =Districts!E6 | G24: =F24*E24*10*Assumptions!$D$8*Assumptions!$E$8/1000000 | H24: =Assumptions!$B$8/Assumptions!$C$8*E24 | I24: =IF(G24=0,0,H24/(G24*1000000)) | J24: high
A25: 24 | B25: Qalyubia | C25: Delta - other | D25: Drip retrofit | E25: =Districts!C7 | F25: =Districts!E7 | G25: =F25*E25*10*Assumptions!$D$8*Assumptions!$E$8/1000000 | H25: =Assumptions!$B$8/Assumptions!$C$8*E25 | I25: =IF(G25=0,0,H25/(G25*1000000)) | J25: high
A26: 25 | B26: Minya | C26: Nile Valley | D26: Drip retrofit | E26: =Districts!C8 | F26: =Districts!E8 | G26: =F26*E26*10*Assumptions!$D$8*Assumptions!$E$8/1000000 | H26: =Assumptions!$B$8/Assumptions!$C$8*E26 | I26: =IF(G26=0,0,H26/(G26*1000000)) | J26: high
A27: 26 | B27: Fayoum | C27: Nile Valley | D27: Drip retrofit | E27: =Districts!C9 | F27: =Districts!E9 | G27: =F27*E27*10*Assumptions!$D$8*Assumptions!$E$8/1000000 | H27: =Assumptions!$B$8/Assumptions!$C$8*E27 | I27: =IF(G27=0,0,H27/(G27*1000000)) | J27: high
A28: 27 | B28: Menoufia | C28: Delta - other | D28: Drip retrofit | E28: =Districts!C10 | F28: =Districts!E10 | G28: =F28*E28*10*Assumptions!$D$8*Assumptions!$E$8/1000000 | H28: =Assumptions!$B$8/Assumptions!$C$8*E28 | I28: =IF(G28=0,0,H28/(G28*1000000)) | J28: high
A29: 28 | B29: Gharbia | C29: Delta - other | D29: Drip retrofit | E29: =Districts!C12 | F29: =Districts!E12 | G29: =F29*E29*10*Assumptions!$D$8*Assumptions!$E$8/1000000 | H29: =Assumptions!$B$8/Assumptions!$C$8*E29 | I29: =IF(G29=0,0,H29/(G29*1000000)) | J29: high
A30: 29 | B30: Giza | C30: Nile Valley | D30: Drip retrofit | E30: =Districts!C13 | F30: =Districts!E13 | G30: =F30*E30*10*Assumptions!$D$8*Assumptions!$E$8/1000000 | H30: =Assumptions!$B$8/Assumptions!$C$8*E30 | I30: =IF(G30=0,0,H30/(G30*1000000)) | J30: medium
A31: 30 | B31: Ismailia | C31: Delta - other | D31: Drip retrofit | E31: =Districts!C15 | F31: =Districts!E15 | G31: =F31*E31*10*Assumptions!$D$8*Assumptions!$E$8/1000000 | H31: =Assumptions!$B$8/Assumptions!$C$8*E31 | I31: =IF(G31=0,0,H31/(G31*1000000)) | J31: medium
A32: 31 | B32: Sharqia | C32: Delta - rice belt | D32: Alternate wetting & drying (rice) | E32: =Districts!C11 | F32: =Districts!E11 | G32: =F32*E32*10*Assumptions!$D$6*Assumptions!$E$6/1000000 | H32: =Assumptions!$B$6/Assumptions!$C$6*E32 | I32: =IF(G32=0,0,H32/(G32*1000000)) | J32: high
A33: 32 | B33: Dakahlia | C33: Delta - rice belt | D33: Alternate wetting & drying (rice) | E33: =Districts!C14 | F33: =Districts!E14 | G33: =F33*E33*10*Assumptions!$D$6*Assumptions!$E$6/1000000 | H33: =Assumptions!$B$6/Assumptions!$C$6*E33 | I33: =IF(G33=0,0,H33/(G33*1000000)) | J33: high
A34: 33 | B34: Kafr El Sheikh | C34: Delta - rice belt | D34: Alternate wetting & drying (rice) | E34: =Districts!C16 | F34: =Districts!E16 | G34: =F34*E34*10*Assumptions!$D$6*Assumptions!$E$6/1000000 | H34: =Assumptions!$B$6/Assumptions!$C$6*E34 | I34: =IF(G34=0,0,H34/(G34*1000000)) | J34: high
A35: 34 | B35: Beheira | C35: Delta - rice belt | D35: Alternate wetting & drying (rice) | E35: =Districts!C17 | F35: =Districts!E17 | G35: =F35*E35*10*Assumptions!$D$6*Assumptions!$E$6/1000000 | H35: =Assumptions!$B$6/Assumptions!$C$6*E35 | I35: =IF(G35=0,0,H35/(G35*1000000)) | J35: high
A36: 35 | B36: Alexandria | C36: Delta - other | D36: Drip retrofit | E36: =Districts!C19 | F36: =Districts!E19 | G36: =F36*E36*10*Assumptions!$D$8*Assumptions!$E$8/1000000 | H36: =Assumptions!$B$8/Assumptions!$C$8*E36 | I36: =IF(G36=0,0,H36/(G36*1000000)) | J36: high
A37: 36 | B37: Damietta | C37: Delta - rice belt | D37: Alternate wetting & drying (rice) | E37: =Districts!C18 | F37: =Districts!E18 | G37: =F37*E37*10*Assumptions!$D$6*Assumptions!$E$6/1000000 | H37: =Assumptions!$B$6/Assumptions!$C$6*E37 | I37: =IF(G37=0,0,H37/(G37*1000000)) | J37: high
A38: 37 | B38: Aswan | C38: Nile Valley | D38: Straw / plastic mulching | E38: =Districts!C2 | F38: =Districts!E2 | G38: =F38*E38*10*Assumptions!$D$7*Assumptions!$E$7/1000000 | H38: =Assumptions!$B$7/Assumptions!$C$7*E38 | I38: =IF(G38=0,0,H38/(G38*1000000)) | J38: medium
A39: 38 | B39: Qena | C39: Nile Valley | D39: Straw / plastic mulching | E39: =Districts!C3 | F39: =Districts!E3 | G39: =F39*E39*10*Assumptions!$D$7*Assumptions!$E$7/1000000 | H39: =Assumptions!$B$7/Assumptions!$C$7*E39 | I39: =IF(G39=0,0,H39/(G39*1000000)) | J39: medium
A40: 39 | B40: Sohag | C40: Nile Valley | D40: Straw / plastic mulching | E40: =Districts!C4 | F40: =Districts!E4 | G40: =F40*E40*10*Assumptions!$D$7*Assumptions!$E$7/1000000 | H40: =Assumptions!$B$7/Assumptions!$C$7*E40 | I40: =IF(G40=0,0,H40/(G40*1000000)) | J40: high
A41: 40 | B41: Assiut | C41: Nile Valley | D41: Straw / plastic mulching | E41: =Districts!C5 | F41: =Districts!E5 | G41: =F41*E41*10*Assumptions!$D$7*Assumptions!$E$7/1000000 | H41: =Assumptions!$B$7/Assumptions!$C$7*E41 | I41: =IF(G41=0,0,H41/(G41*1000000)) | J41: high
A42: 41 | B42: Beni Suef | C42: Nile Valley | D42: Straw / plastic mulching | E42: =Districts!C6 | F42: =Districts!E6 | G42: =F42*E42*10*Assumptions!$D$7*Assumptions!$E$7/1000000 | H42: =Assumptions!$B$7/Assumptions!$C$7*E42 | I42: =IF(G42=0,0,H42/(G42*1000000)) | J42: high
A43: 42 | B43: Qalyubia | C43: Delta - other | D43: Straw / plastic mulching | E43: =Districts!C7 | F43: =Districts!E7 | G43: =F43*E43*10*Assumptions!$D$7*Assumptions!$E$7/1000000 | H43: =Assumptions!$B$7/Assumptions!$C$7*E43 | I43: =IF(G43=0,0,H43/(G43*1000000)) | J43: high
A44: 43 | B44: Minya | C44: Nile Valley | D44: Straw / plastic mulching | E44: =Districts!C8 | F44: =Districts!E8 | G44: =F44*E44*10*Assumptions!$D$7*Assumptions!$E$7/1000000 | H44: =Assumptions!$B$7/Assumptions!$C$7*E44 | I44: =IF(G44=0,0,H44/(G44*1000000)) | J44: high
A45: 44 | B45: Fayoum | C45: Nile Valley | D45: Straw / plastic mulching | E45: =Districts!C9 | F45: =Districts!E9 | G45: =F45*E45*10*Assumptions!$D$7*Assumptions!$E$7/1000000 | H45: =Assumptions!$B$7/Assumptions!$C$7*E45 | I45: =IF(G45=0,0,H45/(G45*1000000)) | J45: high
...

Sheet Allocation
A1: Budget allocation - the decision
A2: Cheapest water first, down the ranked list, until the budget is exhausted. One measure per governorate.
A4: # | B4: Governorate | C4: Intervention | D4: Funded USD | E4: Hectares treated | F4: Water saved Mm3
A5: 1 | B5: Aswan | C5: Laser land levelling | D5: 1190250 | E5: 79350 | F5: 29.5182
A6: 2 | B6: Qena | C6: Laser land levelling | D6: 2737530 | E6: 182502 | F6: 67.817743
A7: 3 | B7: Sohag | C7: Laser land levelling | D7: 2167830 | E7: 144522 | F7: 50.84284
A8: 4 | B8: Assiut | C8: Laser land levelling | D8: 2230020 | E8: 148668 | F8: 48.346834
A9: 5 | B9: Beni Suef | C9: Laser land levelling | D9: 1965810 | E9: 131054 | F9: 41.727594
A10: 6 | B10: Qalyubia | C10: Laser land levelling | D10: 1124325 | E10: 74955 | F10: 22.921239
A11: 7 | B11: Minya | C11: Laser land levelling | D11: 584235 | E11: 38949 | F11: 11.832706
C12: TOTAL | D12: =SUM(D5:D11) | F12: =SUM(F5:F11)
A14: RESULT
A15: Budget | B15: =Assumptions!$B$10
A16: Water recovered - targeted (Mm3) | B16: =F12
A17: Water recovered - area-proportional baseline (Mm3) | B17: 218.1
A18: Advantage of targeting | B18: =IF(B17=0,0,B16/B17-1)
A19: Cost of water - targeted (USD/m3) | B19: =IF(B16=0,0,D12/(B16*1000000))
A20: Cost of water - baseline (USD/m3) | B20: 0.055
A21: Total non-beneficial evaporation, study area (Mm3) | B21: =Districts!I20
A23: The baseline is a Python-computed constant: it depends on the full area-weighted allocation, which does not reduce to a single cell formula. Re-run pipeline/04_rank_and_allocate.py after changing assumptions.

Sheet Information value
A1: How much of the result is actually WaPOR?
A2: The allocation re-run with WaPOR progressively removed. This is the question a reviewer will ask, so we answer it first.
A4: Information available | B4: What that represents | C4: Targeted Mm3 | D4: Baseline Mm3 | E4: Gain | F4: USD/m3
A5: Real per-district evaporation | B5: what WaPOR gives you | C5: 273 | D5: 218.1 | E5: 0.252 | F5: 0.044
A6: Evaporation as a per-system average | B6: an agronomy textbook | C6: 261.7 | D6: 215.4 | E6: 0.215 | F6: 0.0459
A7: Evaporation spatially flat | B7: no satellite at all | C7: 225.4 | D7: 225.4 | E7: 0 | F7: 0.0532
A9: Attributable to satellite DETAIL (full minus per-system) | E9: 0.037
A11: Two honest conclusions:
A12: 1. With evaporation spatially flat, targeting gains nothing. The entire advantage is spatial - that is the real argument for the satellite.
A13: 2. But about two thirds of it is recoverable from a coarse agronomic classification. The part needing genuine satellite detail is the figure in row 9.
A14: Stating this ourselves is worth more than having it derived for us in a review.

Sheet Equity
A1: What an equity floor costs
A2: The equity floor is the share of the budget spread across EVERY district by area before the rest is targeted. Pure cheapest-first funds four governorates out of twenty; no ministry with an equity mandate signs that. Pricing the constraint is more useful than optimising around it.
A4: Equity floor | B4: Governorates funded | C4: Water recovered Mm3 | D4: USD/m3 | E4: Water lost vs pure targeting
A5: 0 | B5: 7 | C5: 273 | D5: 0.044 | E5: 0
A6: 0.25 | B6: 18 | C6: 264.2 | D6: 0.0454 | E6: 0.032
A7: 0.5 | B7: 18 | C7: 253.3 | D7: 0.0474 | E7: 0.072
A8: 0.75 | B8: 18 | C8: 237.9 | D8: 0.0504 | E8: 0.129
A9: 1 | B9: 18 | C9: 218.1 | D9: 0.055 | E9: 0.201
A11: A 25% floor funds every governorate for under 4% of the water. That is the recommendation a budget committee can sign.
A13: Internal check: a 100% floor should reproduce the area-proportional baseline exactly. It does.

Sheet Sensitivity
A1: Does targeting still matter at a different budget?
A2: The advantage is largest when money is scarcest - the correct economic behaviour, and worth saying out loud.
A4: Budget USD | B4: Targeted Mm3 | C4: Baseline Mm3 | D4: Advantage | E4: Governorates funded
A5: 4000000 | B5: 99.029743 | C5: 72.680292 | D5: =IF(C5=0,0,B5/C5-1) | E5: 3
A6: 8000000 | B6: 189.47164 | C6: 145.36058 | D6: =IF(C6=0,0,B6/C6-1) | E6: 5
A7: 12000000 | B7: 273.01812 | C7: 218.04088 | D7: =IF(C7=0,0,B7/C7-1) | E7: 8
A8: 20000000 | B8: 432.4363 | C8: 363.40146 | D8: =IF(C8=0,0,B8/C8-1) | E8: 11
A9: 30000000 | B9: 621.96124 | C9: 545.10219 | D9: =IF(C9=0,0,B9/C9-1) | E9: 14
A10: 50000000 | B10: 927.00838 | C10: 908.50366 | D10: =IF(C10=0,0,B10/C10-1) | E10: 17
A11: 80000000 | B11: 969.14373 | C11: 969.14373 | D11: =IF(C11=0,0,B11/C11-1) | E11: 20
